Workbook

Sheet Default Mapping
A1: EC → S/4 IT0006 | Default Home Mapping
A2: EC fields from doc/bankofcanaT2-Metadata.xml (PerAddressDEFLT). Default target is a SAP documentation candidate; record country exceptions on Secondary Mapping. Check live configuration.
A3: SAP S/4HANA EC replication guide (1H 2605), IT0006, pp. 72–78 and 172 onward: https://help.sap.com/doc/d168209b47c64118b321a67311b98e43/2605/en-US/SF_EC_S4_EE_Data_HCI_en-US.pdf
A5: EC HRIS field | B5: EC OData property | C5: EC address type | D5: S/4 infotype | E5: Default S/4 field | F5: Rule / value mapping | G5: Evidence status | H5: Live configuration check | I5: Notes / decision
A6: startDate | B6: startDate | C6: home | D6: IT0006 | E6: BEGDA | F6: Direct validity date | G6: SAP standard | H6: Pending
A7: endDate | B7: endDate | C7: home | D7: IT0006 | E7: ENDDA | F7: Direct validity date | G7: SAP standard | H7: Pending
A8: addressType | B8: addressType | C8: home | D8: IT0006 | E8: ANSSA | F8: Same field target for all 19 countries; verify home → 1 code mapping | G8: User confirmed common field target | H8: Pending value and runtime check | I8: Subtype 1 appears in supplied screenshots; confirm live ANSSA/SUBTY behavior
A9: country | B9: country | C9: home | D9: IT0006 | E9: LAND1 | F9: Default: country → LAND1; verify EC-to-SAP code conversion | G9: User confirmed default | H9: Pending code and runtime check | I9: EC country code and SAP country key may differ
A10: city | B10: city | C10: home | D10: IT0006 | E10: ORT01 | F10: Default: city → ORT01; see Secondary Mapping | G10: User confirmed default | H10: Pending EC→S/4 runtime check | I10: HK maps to COUNC; JP screenshot target blank; NLD pending review
A11: zip-code | B11: zipCode | C11: home | D11: IT0006 | E11: PSTLZ | F11: Default: zip-code → PSTLZ; preserve postal code as text | G11: User confirmed default | H11: Pending EC→S/4 runtime check | I11: No country exceptions supplied; check length and requiredness by country
A12: address1 | B12: address1 | C12: home | D12: IT0006 | E12: STRAS | F12: Default: address1 → STRAS; use Secondary Mapping for screenshot exceptions | G12: User confirmed default | H12: Pending EC→S/4 runtime check | I12: ERP_WS_10 screenshot has country-specific field targets; template direction to confirm
A13: address2 | B13: address2 | C13: home | D13: IT0006 | F13: No default target; map by country on Secondary Mapping | G13: User confirmed country-dependent | H13: Pending EC→S/4 runtime check | I13: No screenshot row for AUT, BEL, BMU, ISR; leave unresolved
A14: address3 | B14: address3 | C14: home | D14: IT0006 | F14: No default target; map by country on Secondary Mapping | G14: User confirmed country-dependent | H14: Pending EC→S/4 runtime check | I14: Screenshot has 11 in-scope countries; remaining 8 are unresolved
A15: address4 | B15: address4 | C15: home | D15: IT0006 | F15: No default target; map by country on Secondary Mapping | G15: User confirmed country-dependent | H15: Pending EC→S/4 runtime check | I15: Screenshot has 6 in-scope countries; remaining 13 are unresolved
A16: address5 | B16: address5 | C16: home | D16: IT0006 | F16: No default target; map by country on Secondary Mapping | G16: User confirmed country-dependent | H16: Pending EC→S/4 runtime check | I16: Screenshot has 5 in-scope countries; remaining 14 are unresolved
A17: address6 | B17: address6 | C17: home | D17: IT0006 | F17: No default target; map by country on Secondary Mapping | G17: User confirmed country-dependent | H17: Pending EC→S/4 runtime check | I17: Screenshot has 2 in-scope countries; remaining 17 are unresolved
A18: address7 | B18: address7 | C18: home | D18: IT0006 | F18: No in-scope screenshot mapping | G18: Out-of-scope only | H18: Pending EC→S/4 runtime check | I18: Screenshot lists SA and SG only; excluded from scope
A19: address8 | B19: address8 | C19: home | D19: IT0006 | F19: No in-scope screenshot mapping | G19: Out-of-scope only | H19: Pending EC→S/4 runtime check | I19: Screenshot lists SA and SG only; excluded from scope
A20: address9 | B20: address9 | C20: home | D20: IT0006 | F20: No in-scope screenshot mapping | G20: Out-of-scope only | H20: Pending EC→S/4 runtime check | I20: Screenshot lists Saudi Arabia only (country grouping 24); excluded
A21: address10 | B21: address10 | C21: home | D21: IT0006 | F21: Country-specific; record any mapping in Secondary Mapping | G21: Country review | H21: Pending
A22: address11 | B22: address11 | C22: home | D22: IT0006 | F22: Country-specific; record any mapping in Secondary Mapping | G22: Country review | H22: Pending
A23: address12 | B23: address12 | C23: home | D23: IT0006 | F23: Country-specific; record any mapping in Secondary Mapping | G23: Country review | H23: Pending
A24: address13 | B24: address13 | C24: home | D24: IT0006 | F24: Country-specific; record any mapping in Secondary Mapping | G24: Country review | H24: Pending
A25: address20 | B25: address20 | C25: home | D25: IT0006 | F25: Switzerland only; see Secondary Mapping | G25: User confirmed CHE only | H25: Pending EC→S/4 runtime check | I25: No address20 mapping for the other 18 countries in scope
A26: state | B26: state | C26: home | D26: IT0006 | E26: STATE | F26: Default: state → STATE; verify country picklist code conversion | G26: User confirmed default | H26: Pending EC→S/4 runtime check | I26: GBR and IRL county also map to STATE; verify country field selection
A27: province | B27: province | C27: home | D27: IT0006 | F27: Country-specific; code mapping may be required | G27: Country review | H27: Pending
A28: county | B28: county | C28: home | D28: IT0006 | F28: No default target; map by country on Secondary Mapping | G28: User confirmed country-dependent | H28: Pending EC→S/4 runtime check | I28: Screenshot has 9 in-scope countries; remaining 10 are unresolved

Sheet Secondary Mapping
A1: IT0006 | Country Exceptions
A2: Enter one row only when a country needs a different target, transformation, picklist/value mapping or requiredness rule. Blank rows are intentional.
A3: SAP S/4HANA EC replication guide (1H 2605), IT0006, pp. 72–78 and 172 onward: https://help.sap.com/doc/d168209b47c64118b321a67311b98e43/2605/en-US/SF_EC_S4_EE_Data_HCI_en-US.pdf
A5: Country | B5: Country code | C5: EC HRIS field | D5: Default S/4 field | E5: Country S/4 field | F5: Transformation / value map | G5: Reason for exception | H5: EC required? | I5: S/4 required? | J5: Config / payload evidence | K5: Status | L5: Notes | M5: Country View key
A6: China | B6: CHN | C6: address1 | D6: STRAS | E6: LOCAT | G6: Screenshot country exception | J6: User screenshot: ERP_WS_10 / address1 | K6: Direction check pending | L6: SAP country key CN; IT0006 subtype 1; value mapping entity blank | M6: =IF(B6="","",B6&"::"&C6) -> CHN::address1
A7: France | B7: FRA | C7: address1 | D7: STRAS | E7: HSNMR | G7: Screenshot country exception | J7: User screenshot: ERP_WS_10 / address1 | K7: Direction check pending | L7: SAP country key FR; IT0006 subtype 1; value mapping entity blank | M7: =IF(B7="","",B7&"::"&C7) -> FRA::address1
A8: Hong Kong | B8: HKG | C8: address1 | D8: STRAS | E8: LOCAT | G8: Screenshot country exception | J8: User screenshot: ERP_WS_10 / address1 | K8: Direction check pending | L8: SAP country key HK; IT0006 subtype 1; value mapping entity blank | M8: =IF(B8="","",B8&"::"&C8) -> HKG::address1
A9: Japan | B9: JPN | C9: address1 | D9: STRAS | E9: ORT01 | G9: Screenshot country exception | J9: User screenshot: ERP_WS_10 / address1 | K9: Direction check pending | L9: SAP country key JP; IT0006 subtype 1; value mapping entity blank | M9: =IF(B9="","",B9&"::"&C9) -> JPN::address1
A10: Netherlands | B10: NLD | C10: address1 | D10: STRAS | E10: LOCAT | G10: Screenshot country exception | J10: User screenshot: ERP_WS_10 / address1 | K10: Direction check pending | L10: SAP country key NL; IT0006 subtype 1; value mapping entity blank | M10: =IF(B10="","",B10&"::"&C10) -> NLD::address1
A11: Australia | B11: AUS | C11: address2 | E11: HSNMR | G11: Country-dependent mapping | J11: User screenshot: ERP_WS_10 / address2 | K11: Direction check pending | L11: SAP country key AU; IT0006 subtype 1; value mapping entity blank | M11: =IF(B11="","",B11&"::"&C11) -> AUS::address2
A12: Canada | B12: CAN | C12: address2 | E12: LOCAT | G12: Country-dependent mapping | J12: User screenshot: ERP_WS_10 / address2 | K12: Direction check pending | L12: SAP country key CA; IT0006 subtype 1; value mapping entity blank | M12: =IF(B12="","",B12&"::"&C12) -> CAN::address2
A13: Switzerland | B13: CHE | C13: address2 | E13: LOCAT | G13: Country-dependent mapping | J13: User screenshot: ERP_WS_10 / address2 | K13: Direction check pending | L13: SAP country key CH; IT0006 subtype 1; value mapping entity blank | M13: =IF(B13="","",B13&"::"&C13) -> CHE::address2
A14: China | B14: CHN | C14: address2 | E14: STRAS | G14: Country-dependent mapping | J14: User screenshot: ERP_WS_10 / address2 | K14: Direction check pending | L14: SAP country key CN; IT0006 subtype 1; value mapping entity blank | M14: =IF(B14="","",B14&"::"&C14) -> CHN::address2
A15: Colombia | B15: COL | C15: address2 | E15: LOCAT | G15: Country-dependent mapping | J15: User screenshot: ERP_WS_10 / address2 | K15: Direction check pending | L15: SAP country key CO; IT0006 subtype 1; value mapping entity blank | M15: =IF(B15="","",B15&"::"&C15) -> COL::address2
A16: Germany | B16: DEU | C16: address2 | E16: STRAS | G16: Country-dependent mapping | J16: User screenshot: ERP_WS_10 / address2 | K16: Direction check pending | L16: SAP country key DE; IT0006 subtype 1; value mapping entity blank | M16: =IF(B16="","",B16&"::"&C16) -> DEU::address2
A17: Spain | B17: ESP | C17: address2 | E17: HSNMR | G17: Country-dependent mapping | J17: User screenshot: ERP_WS_10 / address2 | K17: Direction check pending | L17: SAP country key ES; IT0006 subtype 1; value mapping entity blank | M17: =IF(B17="","",B17&"::"&C17) -> ESP::address2
A18: France | B18: FRA | C18: address2 | E18: STRAS | G18: Country-dependent mapping | J18: User screenshot: ERP_WS_10 / address2 | K18: Direction check pending | L18: SAP country key FR; IT0006 subtype 1; value mapping entity blank | M18: =IF(B18="","",B18&"::"&C18) -> FRA::address2
A19: United Kingdom | B19: GBR | C19: address2 | E19: LOCAT | G19: Country-dependent mapping | J19: User screenshot: ERP_WS_10 / address2 | K19: Direction check pending | L19: SAP country key GB; IT0006 subtype 1; value mapping entity blank | M19: =IF(B19="","",B19&"::"&C19) -> GBR::address2
A20: Hong Kong | B20: HKG | C20: address2 | E20: STRAS | G20: Country-dependent mapping | J20: User screenshot: ERP_WS_10 / address2 | K20: Direction check pending | L20: SAP country key HK; IT0006 subtype 1; value mapping entity blank | M20: =IF(B20="","",B20&"::"&C20) -> HKG::address2
A21: Ireland | B21: IRL | C21: address2 | E21: LOCAT | G21: Country-dependent mapping | J21: User screenshot: ERP_WS_10 / address2 | K21: Direction check pending | L21: SAP country key IE; IT0006 subtype 1; value mapping entity blank | M21: =IF(B21="","",B21&"::"&C21) -> IRL::address2
A22: India | B22: IND | C22: address2 | E22: HSNMR | G22: Country-dependent mapping | J22: User screenshot: ERP_WS_10 / address2 | K22: Direction check pending | L22: SAP country key IN; IT0006 subtype 1; value mapping entity blank | M22: =IF(B22="","",B22&"::"&C22) -> IND::address2
... A50: Japan | B50: JPN | C50: address6 | E50: LOCAT | G50: Country-dependent mapping | J50: User screenshot: ERP_WS_10 / address6 | K50: Direction check pending | L50: SAP country key JP; IT0006 subtype 1; value mapping not confirmed | M50: =IF(B50="","",B50&"::"&C50) -> JPN::address6
A51: Hong Kong | B51: HKG | C51: city | D51: ORT01 | E51: COUNC | G51: Country exception | J51: User screenshot: ERP_WS_10 / city | K51: Direction check pending | L51: SAP country key HK; IT0006 subtype 1; value mapping entity blank | M51: =IF(B51="","",B51&"::"&C51) -> HKG::city
A52: Japan | B52: JPN | C52: city | D52: ORT01 | G52: Screenshot target field blank | J52: User screenshot: ERP_WS_10 / city | K52: Blank target; review | L52: SAP country key JP; IT0006 subtype 1; do not infer default fallback | M52: =IF(B52="","",B52&"::"&C52) -> JPN::city
A53: Austria | B53: AUT | C53: county | E53: ORT02 | G53: Country-dependent mapping | J53: User screenshot: ERP_WS_10 / county | K53: Direction check pending | L53: SAP country key AT; IT0006 subtype 1; value mapping entity blank | M53: =IF(B53="","",B53&"::"&C53) -> AUT::county
A54: Australia | B54: AUS | C54: county | E54: ORT02 | G54: Country-dependent mapping | J54: User screenshot: ERP_WS_10 / county | K54: Direction check pending | L54: SAP country key AU; IT0006 subtype 1; value mapping entity blank | M54: =IF(B54="","",B54&"::"&C54) -> AUS::county
A55: Switzerland | B55: CHE | C55: county | E55: ORT02 | G55: Country-dependent mapping | J55: User screenshot: ERP_WS_10 / county | K55: Direction check pending | L55: SAP country key CH; IT0006 subtype 1; value mapping entity blank | M55: =IF(B55="","",B55&"::"&C55) -> CHE::county
A56: France | B56: FRA | C56: county | E56: ORT02 | G56: Country-dependent mapping | J56: User screenshot: ERP_WS_10 / county | K56: Direction check pending | L56: SAP country key FR; IT0006 subtype 1; value mapping entity blank | M56: =IF(B56="","",B56&"::"&C56) -> FRA::county
A57: United Kingdom | B57: GBR | C57: county | E57: STATE | G57: Country-dependent mapping | J57: User screenshot: ERP_WS_10 / county | K57: Direction check pending | L57: SAP country key GB; IT0006 subtype 1; value mapping entity blank | M57: =IF(B57="","",B57&"::"&C57) -> GBR::county
A58: Ireland | B58: IRL | C58: county | E58: STATE | G58: Country-dependent mapping | J58: User screenshot: ERP_WS_10 / county | K58: Direction check pending | L58: SAP country key IE; IT0006 subtype 1; value mapping entity blank | M58: =IF(B58="","",B58&"::"&C58) -> IRL::county
A59: India | B59: IND | C59: county | E59: ORT02 | G59: Country-dependent mapping | J59: User screenshot: ERP_WS_10 / county | K59: Direction check pending | L59: SAP country key IN; IT0006 subtype 1; value mapping entity blank | M59: =IF(B59="","",B59&"::"&C59) -> IND::county
A60: Japan | B60: JPN | C60: county | E60: COUNC | G60: Country-dependent mapping | J60: User screenshot: ERP_WS_10 / county | K60: Direction check pending | L60: SAP country key JP; IT0006 subtype 1; value mapping entity blank | M60: =IF(B60="","",B60&"::"&C60) -> JPN::county
A61: United States | B61: USA | C61: county | E61: ORT02 | G61: Country-dependent mapping | J61: User screenshot: ERP_WS_10 / county | K61: Direction check pending | L61: SAP country key US; IT0006 subtype 1; value mapping entity blank | M61: =IF(B61="","",B61&"::"&C61) -> USA::county
M62: =IF(B62="","",B62&"::"&C62)
M63: =IF(B63="","",B63&"::"&C63)
M64: =IF(B64="","",B64&"::"&C64)
M65: =IF(B65="","",B65&"::"&C65)
M66: =IF(B66="","",B66&"::"&C66)
M67: =IF(B67="","",B67&"::"&C67)
M68: =IF(B68="","",B68&"::"&C68)
...

Sheet Countries
A1: IT0006 | Home Address Country Scope
A2: These countries use Default Mapping unless an exception is documented on Secondary Mapping. Check each country’s SAP screen, EC field layout and live configuration.
A3: SAP S/4HANA EC replication guide (1H 2605), IT0006, pp. 72–78 and 172 onward: https://help.sap.com/doc/d168209b47c64118b321a67311b98e43/2605/en-US/SF_EC_S4_EE_Data_HCI_en-US.pdf
A5: Country | B5: ISO3 | C5: EC address type | D5: Mapping rule | E5: Country review | F5: S/4 required fields checked? | G5: Evidence / notes
A6: Canada | B6: CAN | C6: home | D6: Default + recorded exceptions | E6: Pending | F6: Pending
A7: Australia | B7: AUS | C7: home | D7: Default + recorded exceptions | E7: Pending | F7: Pending
A8: Austria | B8: AUT | C8: home | D8: Default + recorded exceptions | E8: Pending | F8: Pending
A9: Belgium | B9: BEL | C9: home | D9: Default + recorded exceptions | E9: Pending | F9: Pending
A10: Bermuda | B10: BMU | C10: home | D10: Default + recorded exceptions | E10: Pending | F10: Pending
A11: China | B11: CHN | C11: home | D11: Default + recorded exceptions | E11: Pending | F11: Pending
A12: Colombia | B12: COL | C12: home | D12: Default + recorded exceptions | E12: Pending | F12: Pending
A13: France | B13: FRA | C13: home | D13: Default + recorded exceptions | E13: Pending | F13: Pending
A14: Hong Kong | B14: HKG | C14: home | D14: Default + recorded exceptions | E14: Pending | F14: Pending
A15: India | B15: IND | C15: home | D15: Default + recorded exceptions | E15: Pending | F15: Pending
A16: Ireland | B16: IRL | C16: home | D16: Default + recorded exceptions | E16: Pending | F16: Pending
A17: Israel | B17: ISR | C17: home | D17: Default + recorded exceptions | E17: Pending | F17: Pending
... A24: Germany | B24: DEU | C24: home | D24: Default + recorded exceptions | E24: Pending | F24: Pending

Sheet Country View
A1: EC → IT0006 | Country Mapping View
A2: Select country | B2: Australia | D2: ISO3 | E2: =IFERROR(INDEX(Countries!$B$6:$B$24,MATCH(B2,Countries!$A$6:$A$24,0)),"") -> AUS
A3: Country entries override the default. “Review: blank target” records an explicit screenshot row with no target field; “Not recorded” has no mapping in this workbook.
A5: EC field | B5: Default IT0006 | C5: Country target | D5: Effective mapping | E5: Source / status
A6: ='Default Mapping'!A6 -> startDate | B6: =IF('Default Mapping'!E6="","",'Default Mapping'!E6) -> BEGDA | C6: =IF(COUNTIFS('Secondary Mapping'!$B$6:$B$300,$E$2,'Secondary Mapping'!$C$6:$C$300,$A6)>0,IFERROR(INDEX('Secondary Mapping'!$E$6:$E$300,MATCH($E$2&"::"&$A6,'Secondary Mapping'!$M$6:$M$300,0))&"",""),"") | D6: =IF(COUNTIFS('Secondary Mapping'!$B$6:$B$300,$E$2,'Secondary Mapping'!$C$6:$C$300,$A6)>0,IF(C6="","Review: blank target",C6),IF(B6="","Not recorded",B6)) -> BEGDA | E6: =IF(COUNTIFS('Secondary Mapping'!$B$6:$B$300,$E$2,'Secondary Mapping'!$C$6:$C$300,$A6)>0,"Secondary Mapping",IF(B6="","Not recorded","Default Mapping")) -> Default Mapping
A7: ='Default Mapping'!A7 -> endDate | B7: =IF('Default Mapping'!E7="","",'Default Mapping'!E7) -> ENDDA | C7: =IF(COUNTIFS('Secondary Mapping'!$B$6:$B$300,$E$2,'Secondary Mapping'!$C$6:$C$300,$A7)>0,IFERROR(INDEX('Secondary Mapping'!$E$6:$E$300,MATCH($E$2&"::"&$A7,'Secondary Mapping'!$M$6:$M$300,0))&"",""),"") | D7: =IF(COUNTIFS('Secondary Mapping'!$B$6:$B$300,$E$2,'Secondary Mapping'!$C$6:$C$300,$A7)>0,IF(C7="","Review: blank target",C7),IF(B7="","Not recorded",B7)) -> ENDDA | E7: =IF(COUNTIFS('Secondary Mapping'!$B$6:$B$300,$E$2,'Secondary Mapping'!$C$6:$C$300,$A7)>0,"Secondary Mapping",IF(B7="","Not recorded","Default Mapping")) -> Default Mapping
A8: ='Default Mapping'!A8 -> addressType | B8: =IF('Default Mapping'!E8="","",'Default Mapping'!E8) -> ANSSA | C8: =IF(COUNTIFS('Secondary Mapping'!$B$6:$B$300,$E$2,'Secondary Mapping'!$C$6:$C$300,$A8)>0,IFERROR(INDEX('Secondary Mapping'!$E$6:$E$300,MATCH($E$2&"::"&$A8,'Secondary Mapping'!$M$6:$M$300,0))&"",""),"") | D8: =IF(COUNTIFS('Secondary Mapping'!$B$6:$B$300,$E$2,'Secondary Mapping'!$C$6:$C$300,$A8)>0,IF(C8="","Review: blank target",C8),IF(B8="","Not recorded",B8)) -> ANSSA | E8: =IF(COUNTIFS('Secondary Mapping'!$B$6:$B$300,$E$2,'Secondary Mapping'!$C$6:$C$300,$A8)>0,"Secondary Mapping",IF(B8="","Not recorded","Default Mapping")) -> Default Mapping
A9: ='Default Mapping'!A9 -> country | B9: =IF('Default Mapping'!E9="","",'Default Mapping'!E9) -> LAND1 | C9: =IF(COUNTIFS('Secondary Mapping'!$B$6:$B$300,$E$2,'Secondary Mapping'!$C$6:$C$300,$A9)>0,IFERROR(INDEX('Secondary Mapping'!$E$6:$E$300,MATCH($E$2&"::"&$A9,'Secondary Mapping'!$M$6:$M$300,0))&"",""),"") | D9: =IF(COUNTIFS('Secondary Mapping'!$B$6:$B$300,$E$2,'Secondary Mapping'!$C$6:$C$300,$A9)>0,IF(C9="","Review: blank target",C9),IF(B9="","Not recorded",B9)) -> LAND1 | E9: =IF(COUNTIFS('Secondary Mapping'!$B$6:$B$300,$E$2,'Secondary Mapping'!$C$6:$C$300,$A9)>0,"Secondary Mapping",IF(B9="","Not recorded","Default Mapping")) -> Default Mapping
A10: ='Default Mapping'!A10 -> city | B10: =IF('Default Mapping'!E10="","",'Default Mapping'!E10) -> ORT01 | C10: =IF(COUNTIFS('Secondary Mapping'!$B$6:$B$300,$E$2,'Secondary Mapping'!$C$6:$C$300,$A10)>0,IFERROR(INDEX('Secondary Mapping'!$E$6:$E$300,MATCH($E$2&"::"&$A10,'Secondary Mapping'!$M$6:$M$300,0))&"",""),"") | D10: =IF(COUNTIFS('Secondary Mapping'!$B$6:$B$300,$E$2,'Secondary Mapping'!$C$6:$C$300,$A10)>0,IF(C10="","Review: blank target",C10),IF(B10="","Not recorded",B10)) -> ORT01 | E10: =IF(COUNTIFS('Secondary Mapping'!$B$6:$B$300,$E$2,'Secondary Mapping'!$C$6:$C$300,$A10)>0,"Secondary Mapping",IF(B10="","Not recorded","Default Mapping")) -> Default Mapping
A11: ='Default Mapping'!A11 -> zip-code | B11: =IF('Default Mapping'!E11="","",'Default Mapping'!E11) -> PSTLZ | C11: =IF(COUNTIFS('Secondary Mapping'!$B$6:$B$300,$E$2,'Secondary Mapping'!$C$6:$C$300,$A11)>0,IFERROR(INDEX('Secondary Mapping'!$E$6:$E$300,MATCH($E$2&"::"&$A11,'Secondary Mapping'!$M$6:$M$300,0))&"",""),"") | D11: =IF(COUNTIFS('Secondary Mapping'!$B$6:$B$300,$E$2,'Secondary Mapping'!$C$6:$C$300,$A11)>0,IF(C11="","Review: blank target",C11),IF(B11="","Not recorded",B11)) -> PSTLZ | E11: =IF(COUNTIFS('Secondary Mapping'!$B$6:$B$300,$E$2,'Secondary Mapping'!$C$6:$C$300,$A11)>0,"Secondary Mapping",IF(B11="","Not recorded","Default Mapping")) -> Default Mapping
A12: ='Default Mapping'!A12 -> address1 | B12: =IF('Default Mapping'!E12="","",'Default Mapping'!E12) -> STRAS | C12: =IF(COUNTIFS('Secondary Mapping'!$B$6:$B$300,$E$2,'Secondary Mapping'!$C$6:$C$300,$A12)>0,IFERROR(INDEX('Secondary Mapping'!$E$6:$E$300,MATCH($E$2&"::"&$A12,'Secondary Mapping'!$M$6:$M$300,0))&"",""),"") | D12: =IF(COUNTIFS('Secondary Mapping'!$B$6:$B$300,$E$2,'Secondary Mapping'!$C$6:$C$300,$A12)>0,IF(C12="","Review: blank target",C12),IF(B12="","Not recorded",B12)) -> STRAS | E12: =IF(COUNTIFS('Secondary Mapping'!$B$6:$B$300,$E$2,'Secondary Mapping'!$C$6:$C$300,$A12)>0,"Secondary Mapping",IF(B12="","Not recorded","Default Mapping")) -> Default Mapping
A13: ='Default Mapping'!A13 -> address2 | B13: =IF('Default Mapping'!E13="","",'Default Mapping'!E13) | C13: =IF(COUNTIFS('Secondary Mapping'!$B$6:$B$300,$E$2,'Secondary Mapping'!$C$6:$C$300,$A13)>0,IFERROR(INDEX('Secondary Mapping'!$E$6:$E$300,MATCH($E$2&"::"&$A13,'Secondary Mapping'!$M$6:$M$300,0))&"",""),"") -> HSNMR | D13: =IF(COUNTIFS('Secondary Mapping'!$B$6:$B$300,$E$2,'Secondary Mapping'!$C$6:$C$300,$A13)>0,IF(C13="","Review: blank target",C13),IF(B13="","Not recorded",B13)) -> HSNMR | E13: =IF(COUNTIFS('Secondary Mapping'!$B$6:$B$300,$E$2,'Secondary Mapping'!$C$6:$C$300,$A13)>0,"Secondary Mapping",IF(B13="","Not recorded","Default Mapping")) -> Secondary Mapping
A14: ='Default Mapping'!A14 -> address3 | B14: =IF('Default Mapping'!E14="","",'Default Mapping'!E14) | C14: =IF(COUNTIFS('Secondary Mapping'!$B$6:$B$300,$E$2,'Secondary Mapping'!$C$6:$C$300,$A14)>0,IFERROR(INDEX('Secondary Mapping'!$E$6:$E$300,MATCH($E$2&"::"&$A14,'Secondary Mapping'!$M$6:$M$300,0))&"",""),"") -> POSTA | D14: =IF(COUNTIFS('Secondary Mapping'!$B$6:$B$300,$E$2,'Secondary Mapping'!$C$6:$C$300,$A14)>0,IF(C14="","Review: blank target",C14),IF(B14="","Not recorded",B14)) -> POSTA | E14: =IF(COUNTIFS('Secondary Mapping'!$B$6:$B$300,$E$2,'Secondary Mapping'!$C$6:$C$300,$A14)>0,"Secondary Mapping",IF(B14="","Not recorded","Default Mapping")) -> Secondary Mapping
A15: ='Default Mapping'!A15 -> address4 | B15: =IF('Default Mapping'!E15="","",'Default Mapping'!E15) | C15: =IF(COUNTIFS('Secondary Mapping'!$B$6:$B$300,$E$2,'Secondary Mapping'!$C$6:$C$300,$A15)>0,IFERROR(INDEX('Secondary Mapping'!$E$6:$E$300,MATCH($E$2&"::"&$A15,'Secondary Mapping'!$M$6:$M$300,0))&"",""),"") -> LOCAT | D15: =IF(COUNTIFS('Secondary Mapping'!$B$6:$B$300,$E$2,'Secondary Mapping'!$C$6:$C$300,$A15)>0,IF(C15="","Review: blank target",C15),IF(B15="","Not recorded",B15)) -> LOCAT | E15: =IF(COUNTIFS('Secondary Mapping'!$B$6:$B$300,$E$2,'Secondary Mapping'!$C$6:$C$300,$A15)>0,"Secondary Mapping",IF(B15="","Not recorded","Default Mapping")) -> Secondary Mapping
A16: ='Default Mapping'!A16 -> address5 | B16: =IF('Default Mapping'!E16="","",'Default Mapping'!E16) | C16: =IF(COUNTIFS('Secondary Mapping'!$B$6:$B$300,$E$2,'Secondary Mapping'!$C$6:$C$300,$A16)>0,IFERROR(INDEX('Secondary Mapping'!$E$6:$E$300,MATCH($E$2&"::"&$A16,'Secondary Mapping'!$M$6:$M$300,0))&"",""),"") | D16: =IF(COUNTIFS('Secondary Mapping'!$B$6:$B$300,$E$2,'Secondary Mapping'!$C$6:$C$300,$A16)>0,IF(C16="","Review: blank target",C16),IF(B16="","Not recorded",B16)) -> Not recorded | E16: =IF(COUNTIFS('Secondary Mapping'!$B$6:$B$300,$E$2,'Secondary Mapping'!$C$6:$C$300,$A16)>0,"Secondary Mapping",IF(B16="","Not recorded","Default Mapping")) -> Not recorded
A17: ='Default Mapping'!A17 -> address6 | B17: =IF('Default Mapping'!E17="","",'Default Mapping'!E17) | C17: =IF(COUNTIFS('Secondary Mapping'!$B$6:$B$300,$E$2,'Secondary Mapping'!$C$6:$C$300,$A17)>0,IFERROR(INDEX('Secondary Mapping'!$E$6:$E$300,MATCH($E$2&"::"&$A17,'Secondary Mapping'!$M$6:$M$300,0))&"",""),"") | D17: =IF(COUNTIFS('Secondary Mapping'!$B$6:$B$300,$E$2,'Secondary Mapping'!$C$6:$C$300,$A17)>0,IF(C17="","Review: blank target",C17),IF(B17="","Not recorded",B17)) -> Not recorded | E17: =IF(COUNTIFS('Secondary Mapping'!$B$6:$B$300,$E$2,'Secondary Mapping'!$C$6:$C$300,$A17)>0,"Secondary Mapping",IF(B17="","Not recorded","Default Mapping")) -> Not recorded
... A28: ='Default Mapping'!A28 -> county | B28: =IF('Default Mapping'!E28="","",'Default Mapping'!E28) | C28: =IF(COUNTIFS('Secondary Mapping'!$B$6:$B$300,$E$2,'Secondary Mapping'!$C$6:$C$300,$A28)>0,IFERROR(INDEX('Secondary Mapping'!$E$6:$E$300,MATCH($E$2&"::"&$A28,'Secondary Mapping'!$M$6:$M$300,0))&"",""),"") -> ORT02 | D28: =IF(COUNTIFS('Secondary Mapping'!$B$6:$B$300,$E$2,'Secondary Mapping'!$C$6:$C$300,$A28)>0,IF(C28="","Review: blank target",C28),IF(B28="","Not recorded",B28)) -> ORT02 | E28: =IF(COUNTIFS('Secondary Mapping'!$B$6:$B$300,$E$2,'Secondary Mapping'!$C$6:$C$300,$A28)>0,"Secondary Mapping",IF(B28="","Not recorded","Default Mapping")) -> Secondary Mapping
